<?xml version="1.0" encoding="utf-8"?>
<!-- This URDF was automatically created by SolidWorks to URDF Exporter! Originally created by Stephen Brawner (brawner@gmail.com) 
     Commit Version: 1.6.0-4-g7f85cfe  Build Version: 1.6.7995.38578
     For more information, please see http://wiki.ros.org/sw_urdf_exporter -->
<robot
  name="bexter_dummy_urdf">
  <link
    name="base_link">
    <inertial>
      <origin
        xyz="0.58329 0.65212 1.0658"
        rpy="0 0 0" />
      <mass
        value="41.61" />
      <inertia
        ixx="5.8669"
        ixy="-4.7843E-05"
        ixz="-2.3842E-08"
        iyy="7.1963"
        iyz="1.877E-07"
        izz="1.5502" />
    </inertial>
    <visual>
      <origin
        xyz="0 0 0"
        rpy="0 0 0" />
      <geometry>
        <mesh
          filename="package://bexter_dummy_urdf/meshes/base_link.STL" />
      </geometry>
      <material
        name="">
        <color
          rgba="0.79216 0.81961 0.93333 1" />
      </material>
    </visual>
    <collision>
      <origin
        xyz="0 0 0"
        rpy="0 0 0" />
      <geometry>
        <mesh
          filename="package://bexter_dummy_urdf/meshes/base_link.STL" />
      </geometry>
    </collision>
  </link>
  <link
    name="link_1">
    <inertial>
      <origin
        xyz="-3.8722E-05 0.026725 -0.0011003"
        rpy="0 0 0" />
      <mass
        value="0.10747" />
      <inertia
        ixx="3.0053E-05"
        ixy="-1.8688E-08"
        ixz="-1.4411E-07"
        iyy="1.7362E-05"
        iyz="7.7363E-08"
        izz="2.8037E-05" />
    </inertial>
    <visual>
      <origin
        xyz="0 0 0"
        rpy="0 0 0" />
      <geometry>
        <mesh
          filename="package://bexter_dummy_urdf/meshes/link_1.STL" />
      </geometry>
      <material
        name="">
        <color
          rgba="0.79216 0.81961 0.93333 1" />
      </material>
    </visual>
    <collision>
      <origin
        xyz="0 0 0"
        rpy="0 0 0" />
      <geometry>
        <mesh
          filename="package://bexter_dummy_urdf/meshes/link_1.STL" />
      </geometry>
    </collision>
  </link>
  <joint
    name="joint0"
    type="revolute">
    <origin
      xyz="0.43204 -1.1835 0.85662"
      rpy="1.5708 0 3.0727" />
    <parent
      link="base_link" />
    <child
      link="link_1" />
    <axis
      xyz="0 1 0" />
    <limit
      lower="-2.61"
      upper="2.61"
      effort="1.5"
      velocity="1.9" />
  </joint>
  <link
    name="link_2">
    <inertial>
      <origin
        xyz="0.0064234 -0.098979 -0.00044329"
        rpy="0 0 0" />
      <mass
        value="0.092465" />
      <inertia
        ixx="9.2514E-05"
        ixy="4.2585E-06"
        ixz="-2.5701E-07"
        iyy="2.7193E-05"
        iyz="-2.9389E-07"
        izz="8.8807E-05" />
    </inertial>
    <visual>
      <origin
        xyz="0 0 0"
        rpy="0 0 0" />
      <geometry>
        <mesh
          filename="package://bexter_dummy_urdf/meshes/link_2.STL" />
      </geometry>
      <material
        name="">
        <color
          rgba="0.79216 0.81961 0.93333 1" />
      </material>
    </visual>
    <collision>
      <origin
        xyz="0 0 0"
        rpy="0 0 0" />
      <geometry>
        <mesh
          filename="package://bexter_dummy_urdf/meshes/link_2.STL" />
      </geometry>
    </collision>
  </link>
  <joint
    name="joint1"
    type="revolute">
    <origin
      xyz="0 0.01 0"
      rpy="3.1371 0.00014488 -3.0768" />
    <parent
      link="link_1" />
    <child
      link="link_2" />
    <axis
      xyz="0.068848 0 0.99763" />
    <limit
      lower="-2.61"
      upper="2.61"
      effort="1.5"
      velocity="1.9" />
  </joint>
  <link
    name="end_effector">
    <inertial>
      <origin
        xyz="0.11395 -0.0026249 -0.0082787"
        rpy="0 0 0" />
      <mass
        value="0.28572" />
      <inertia
        ixx="7.2014E-05"
        ixy="1.9139E-06"
        ixz="5.6288E-06"
        iyy="0.00015447"
        iyz="-1.2954E-07"
        izz="0.00015208" />
    </inertial>
    <visual>
      <origin
        xyz="0 0 0"
        rpy="0 0 0" />
      <geometry>
        <mesh
          filename="package://bexter_dummy_urdf/meshes/end_effector.STL" />
      </geometry>
      <material
        name="">
        <color
          rgba="0.79216 0.81961 0.93333 1" />
      </material>
    </visual>
    <collision>
      <origin
        xyz="0 0 0"
        rpy="0 0 0" />
      <geometry>
        <mesh
          filename="package://bexter_dummy_urdf/meshes/end_effector.STL" />
      </geometry>
    </collision>
  </link>
  <joint
    name="end_effector"
    type="revolute">
    <origin
      xyz="0.013043 -0.20096 -0.0009001"
      rpy="0.006038 -0.00026465 0.087604" />
    <parent
      link="link_2" />
    <child
      link="end_effector" />
    <axis
      xyz="0.068848 0 0.99763" />
    <limit
      lower="-2.61"
      upper="2.61"
      effort="1.5"
      velocity="1.9" />
  </joint>
</robot>