<?xml version="1.0" encoding="utf-8"?>
<!-- This URDF was automatically created by SolidWorks to URDF Exporter! Originally created by Stephen Brawner (brawner@gmail.com) 
     Commit Version: 1.6.0-4-g7f85cfe  Build Version: 1.6.7995.38578
     For more information, please see http://wiki.ros.org/sw_urdf_exporter -->
<robot
  name="bexter_collisional_urdf">
  <link
    name="base_link">
    <inertial>
      <origin
        xyz="0.17778 -0.038961 0.060231"
        rpy="0 0 0" />
      <mass
        value="56.299" />
      <inertia
        ixx="9.8922"
        ixy="0.10623"
        ixz="0.66639"
        iyy="3.8999"
        iyz="-0.14604"
        izz="11.264" />
    </inertial>
    <visual>
      <origin
        xyz="0 0 0"
        rpy="0 0 0" />
      <geometry>
        <mesh
          filename="package://bexter_collisional_urdf/meshes/base_link.STL" />
      </geometry>
      <material
        name="">
        <color
          rgba="0.76078 0.4 0.18039 0.3" />
      </material>
    </visual>
    <collision>
      <origin
        xyz="0 0 0"
        rpy="0 0 0" />
      <geometry>
        <mesh
          filename="package://bexter_collisional_urdf/meshes/base_link.STL" />
      </geometry>
    </collision>
  </link>
  <link
    name="link_0">
    <inertial>
      <origin
        xyz="6.6613E-16 -2.2204E-16 -0.025875"
        rpy="0 0 0" />
      <mass
        value="0.0603" />
      <inertia
        ixx="2.186E-05"
        ixy="8.6681E-21"
        ixz="-2.2685E-21"
        iyy="1.7537E-05"
        iyz="-1.2324E-20"
        izz="1.2483E-05" />
    </inertial>
    <visual>
      <origin
        xyz="0 0 0"
        rpy="0 0 0" />
      <geometry>
        <mesh
          filename="package://bexter_collisional_urdf/meshes/link_0.STL" />
      </geometry>
      <material
        name="">
        <color
          rgba="0.76078 0.4 0.18039 0.3" />
      </material>
    </visual>
    <collision>
      <origin
        xyz="0 0 0"
        rpy="0 0 0" />
      <geometry>
        <mesh
          filename="package://bexter_collisional_urdf/meshes/link_0.STL" />
      </geometry>
    </collision>
  </link>
  <joint
    name="joint_1"
    type="continuous">
    <origin
      xyz="0.02685 -0.16355 0.3323"
      rpy="0 0 0" />
    <parent
      link="base_link" />
    <child
      link="link_0" />
    <axis
      xyz="0 0 1" />
    <limit
      lower="0"
      upper="0"
      effort="1.4"
      velocity="0.9" />
  </joint>
  <link
    name="link_1">
    <inertial>
      <origin
        xyz="-3.1E-05 6.2E-05 -0.11735"
        rpy="0 0 0" />
      <mass
        value="0.45544" />
      <inertia
        ixx="0.0014337"
        ixy="-1.9071E-20"
        ixz="-5.7383E-20"
        iyy="0.0014286"
        iyz="-7.8036E-21"
        izz="0.00018256" />
    </inertial>
    <visual>
      <origin
        xyz="0 0 0"
        rpy="0 0 0" />
      <geometry>
        <mesh
          filename="package://bexter_collisional_urdf/meshes/link_1.STL" />
      </geometry>
      <material
        name="">
        <color
          rgba="0.76078 0.4 0.18039 0.3" />
      </material>
    </visual>
    <collision>
      <origin
        xyz="0 0 0"
        rpy="0 0 0" />
      <geometry>
        <mesh
          filename="package://bexter_collisional_urdf/meshes/link_1.STL" />
      </geometry>
    </collision>
  </link>
  <joint
    name="joint_2"
    type="continuous">
    <origin
      xyz="0 0 -0.0405"
      rpy="0 0 0" />
    <parent
      link="link_0" />
    <child
      link="link_1" />
    <axis
      xyz="0 1 0" />
    <limit
      lower="0"
      upper="0"
      effort="1.4"
      velocity="0.9" />
  </joint>
  <link
    name="link_2">
    <inertial>
      <origin
        xyz="0.10378 -6.2172E-15 3.1E-05"
        rpy="0 0 0" />
      <mass
        value="0.39512" />
      <inertia
        ixx="0.00017007"
        ixy="4.4271E-17"
        ixz="-3.7918E-20"
        iyy="0.00086122"
        iyz="-1.0186E-19"
        izz="0.00086201" />
    </inertial>
    <visual>
      <origin
        xyz="0 0 0"
        rpy="0 0 0" />
      <geometry>
        <mesh
          filename="package://bexter_collisional_urdf/meshes/link_2.STL" />
      </geometry>
      <material
        name="">
        <color
          rgba="0.76078 0.4 0.18039 0.3" />
      </material>
    </visual>
    <collision>
      <origin
        xyz="0 0 0"
        rpy="0 0 0" />
      <geometry>
        <mesh
          filename="package://bexter_collisional_urdf/meshes/link_2.STL" />
      </geometry>
    </collision>
  </link>
  <joint
    name="joint_3"
    type="continuous">
    <origin
      xyz="0 6.2E-05 -0.2209"
      rpy="0 0 0" />
    <parent
      link="link_1" />
    <child
      link="link_2" />
    <axis
      xyz="0 1 0" />
    <limit
      lower="0"
      upper="0"
      effort="1.4"
      velocity="0.9" />
  </joint>
  <link
    name="end_effector">
    <inertial>
      <origin
        xyz="-0.0254 -0.022225 0.022225"
        rpy="0 0 0" />
      <mass
        value="0.10037" />
      <inertia
        ixx="3.3052E-05"
        ixy="3.3568E-19"
        ixz="1.062E-20"
        iyy="3.8111E-05"
        iyz="1.7609E-20"
        izz="3.8111E-05" />
    </inertial>
    <visual>
      <origin
        xyz="0 0 0"
        rpy="0 0 0" />
      <geometry>
        <mesh
          filename="package://bexter_collisional_urdf/meshes/end_effector.STL" />
      </geometry>
      <material
        name="">
        <color
          rgba="0.76078 0.4 0.18039 0.3" />
      </material>
    </visual>
    <collision>
      <origin
        xyz="0 0 0"
        rpy="0 0 0" />
      <geometry>
        <mesh
          filename="package://bexter_collisional_urdf/meshes/end_effector.STL" />
      </geometry>
    </collision>
  </link>
  <joint
    name="end_effector_joint"
    type="fixed">
    <origin
      xyz="0.2312 0.022225 -0.022194"
      rpy="0 0 0" />
    <parent
      link="link_2" />
    <child
      link="end_effector" />
    <axis
      xyz="0 0 0" />
  </joint>
</robot>